Workbook

Sheet Assumptions
A1: NIKE, Inc. — Operating Assumptions
A4: DRIVERS — edit the blue cells to re-run the entire model
B5: FY2022A | C5: FY2023A | D5: FY2024A | E5: FY2025E | F5: FY2026E | G5: FY2027E
A6: Growth & Margin
A7: Revenue growth % | C7: =IS!C7/IS!B7-1 -> 0.096488975 | D7: =IS!D7/IS!C7-1 -> 0.0028310912 | E7: ='Live Valuation Engine'!B15 -> 0.005 | F7: ='Live Valuation Engine'!C15 -> 0.035 | G7: ='Live Valuation Engine'!D15 -> 0.045
A8: Gross margin % | B8: =IS!B9/IS!B7 -> 0.45983729 | C8: =IS!C9/IS!C7 -> 0.43524611 | D8: =IS!D9/IS!D7 -> 0.44682839 | E8: ='Live Valuation Engine'!E15 -> 0.445 | F8: ='Live Valuation Engine'!F15 -> 0.45 | G8: ='Live Valuation Engine'!G15 -> 0.453
A9: Demand creation % of revenue | B9: =IS!B11/IS!B7 -> 0.082423464 | C9: =IS!C11/IS!C7 -> 0.079270555 | D9: =IS!D11/IS!D7 -> 0.083349558 | E9: 0.084 | F9: 0.084 | G9: 0.083
A10: Operating overhead % of revenue | B10: =IS!B12/IS!B7 -> 0.23451081 | C10: =IS!C12/IS!C7 -> 0.24048656 | D10: =IS!D12/IS!D7 -> 0.23702348 | E10: 0.234 | F10: 0.231 | G10: 0.228
A11: Other (income) expense, net ($mm) | B11: =IS!B17 -> -181 | C11: =IS!C17 -> -280 | D11: =IS!D17 -> 62 | E11: 50 | F11: 50 | G11: 50
A12: Effective tax rate % | B12: =IS!B20/IS!B19 -> 0.090963765 | C12: =IS!C20/IS!C19 -> 0.18252177 | D12: =IS!D20/IS!D19 -> 0.13531553 | E12: 0.16 | F12: 0.17 | G12: 0.175
A14: Working Capital (days)
A15: DSO — days sales outstanding | D15: =BS!D9/IS!D7*365 -> 31.644893 | E15: 31.5 | F15: 31.5 | G15: 31.5
A16: DIO — days inventory outstanding | D16: =BS!D10/IS!D8*365 -> 96.555681 | E16: 96 | F16: 94 | G16: 92
A17: DPO — days payable outstanding | D17: =BS!D28/IS!D8*365 -> 34.274954 | E17: 34.3 | F17: 34.3 | G17: 34.3
A18: Prepaid & other CA % of revenue | D18: =BS!D11/IS!D7 -> 0.035940968 | E18: 0.036 | F18: 0.036 | G18: 0.036
A19: Accrued liabilities % of revenue | D19: =BS!D29/IS!D7 -> 0.10938048 | E19: 0.109 | F19: 0.109 | G19: 0.109
A20: Income taxes payable % of tax expense | D20: =BS!D30/IS!D20 -> 0.32623318 | E20: 0.326 | F20: 0.326 | G20: 0.326
A22: Capital & Cash Flow
A23: Capital expenditures % of revenue | B23: =-CF!B15/IS!B7 -> 0.01620638 | C23: =-CF!C15/IS!C7 -> 0.018392331 | D23: =-CF!D15/IS!D7 -> 0.018457225 | E23: 0.019 | F23: 0.019 | G23: 0.019
A24: D&A % of revenue | D24: 0.0155 | E24: 0.0155 | F24: 0.0155 | G24: 0.0155
A25: Stock-based compensation ($mm) | D25: 783 | E25: 800 | F25: 840 | G25: 880
A26: Share repurchases ($mm) | B26: =-CF!B22 -> 4034 | C26: =-CF!C22 -> 4756 | D26: =-CF!D22 -> 4260 | E26: 4400 | F26: 4600 | G26: 4800
A27: Dividend growth % | C27: =-CF!C23/-CF!B23-1 -> 0.093766938 | D27: =-CF!D23/-CF!C23-1 -> 0.10455897 | E27: 0.08 | F27: 0.075 | G27: 0.07
A28: Scheduled debt repayment ($mm) | E28: 1000 | F28: 0 | G28: 500
A29: Change in short-term investments ($mm) | B29: =-CF!B16 -> -1846 | C29: =-CF!C16 -> 858 | D29: =-CF!D16 -> 728 | E29: 0 | F29: 0 | G29: 0
A30: Interest rate earned on cash & ST inv. % | E30: 0.038 | F30: 0.036 | G30: 0.035
A31: Interest rate paid on total debt % | E31: 0.028 | F31: 0.028 | G31: 0.028
A32: Diluted share count change % | C32: =IS!C23/IS!B23-1 -> -0.026317423 | D32: =IS!D23/IS!C23-1 -> -0.026136291 | E32: -0.025 | F32: -0.025 | G32: -0.025
A35: SOURCE & METHOD NOTES

Sheet Live Valuation Engine
A1: NIKE, Inc. — Live Valuation Engine
A4: SCENARIO SWITCH — the single assumption cell that drives the entire workbook
A5: Active scenario | C5: Base | E5: ← change this cell only
A7: SCENARIO DRIVER LIBRARY — documented inputs; edit only here to redefine a scenario
A8: Scenario | B8: Rev growth FY25E | C8: Rev growth FY26E | D8: Rev growth FY27E | E8: Gross margin FY25E | F8: Gross margin FY26E | G8: Gross margin FY27E | H8: Comps/precedent tier
A9: Bear | B9: -0.01 | C9: 0.01 | D9: 0.02 | E9: 0.43 | F9: 0.435 | G9: 0.438 | H9: Low
A10: Base | B10: 0.005 | C10: 0.035 | D10: 0.045 | E10: 0.445 | F10: 0.45 | G10: 0.453 | H10: Median
A11: Bull | B11: 0.03 | C11: 0.06 | D11: 0.07 | E11: 0.455 | F11: 0.46 | G11: 0.465 | H11: High
A13: ACTIVE DRIVERS (LIVE) — INDEX/MATCH pull from the library row matching the switch
A14: Scenario | B14: Rev growth FY25E | C14: Rev growth FY26E | D14: Rev growth FY27E | E14: Gross margin FY25E | F14: Gross margin FY26E | G14: Gross margin FY27E | H14: Comps/precedent tier
A15: =$C$5 -> Base | B15: =INDEX(B$9:B$11,MATCH($C$5,$A$9:$A$11,0)) -> 0.005 | C15: =INDEX(C$9:C$11,MATCH($C$5,$A$9:$A$11,0)) -> 0.035 | D15: =INDEX(D$9:D$11,MATCH($C$5,$A$9:$A$11,0)) -> 0.045 | E15: =INDEX(E$9:E$11,MATCH($C$5,$A$9:$A$11,0)) -> 0.445 | F15: =INDEX(F$9:F$11,MATCH($C$5,$A$9:$A$11,0)) -> 0.45 | G15: =INDEX(G$9:G$11,MATCH($C$5,$A$9:$A$11,0)) -> 0.453 | H15: =INDEX($H$9:$H$11,MATCH($C$5,$A$9:$A$11,0)) -> Median
A17: VALUATION TIER LOOKUP — Comps & Precedents outputs indexed by tier
A18: Tier | B18: Comps EV/Revenue price | C18: Comps EV/EBITDA price | D18: Precedent EV/EBITDA price
A19: Low | B19: =Comps!G30 -> 19.4418 | C19: =Comps!G31 -> 26.922084 | D19: =Precedents!G24 -> 36.197568
A20: Median | B20: =Comps!G28 -> 41.623603 | C20: =Comps!G29 -> 51.113608 | D20: =Precedents!G23 -> 56.833509
A21: High | B21: =Comps!G32 -> 179.19626 | C21: =Comps!G33 -> 139.78345 | D21: =Precedents!G25 -> 76.30072
A23: LIVE VALUATION OUTPUT — recalculates the instant the switch above changes
A24: Methodology | B24: Implied Price ($) | C24: Live link
A25: DCF — unlevered FCF (active scenario) | B25: =DCF!C37 -> 62.048819 | C25: DCF!C37
A26: Trading comps — EV/Revenue (tier-matched) | B26: =INDEX($B$19:$B$21,MATCH('Live Valuation Engine'!H15,$A$19:$A$21,0)) -> 41.623603 | C26: INDEX/MATCH -> Comps!G28:G33
A27: Trading comps — EV/EBITDA (tier-matched) | B27: =INDEX($C$19:$C$21,MATCH('Live Valuation Engine'!H15,$A$19:$A$21,0)) -> 51.113608 | C27: INDEX/MATCH -> Comps!G28:G33
A28: Precedent transactions — EV/EBITDA (tier-matched) | B28: =INDEX($D$19:$D$21,MATCH('Live Valuation Engine'!H15,$A$19:$A$21,0)) -> 56.833509 | C28: INDEX/MATCH -> Precedents!G23:G25
A29: Precedent transactions — EV/Revenue (median only) | B29: =Precedents!G26 -> 43.987812 | C29: Precedents!G26
A30: LBO — sponsor-affordable value (reference, not scenario-linked) | B30: ='Football Field'!C10 -> 45.339762 | C30: Football Field!C10
A32: Blended range (excl. LBO) — Low / Mid / High
A33: Low | B33: =MIN(B25,B26,B27,B28) -> 41.623603
A34: Midpoint | B34: =MEDIAN(B25,B26,B27,B28) -> 53.973558
A35: High | B35: =MAX(B25,B26,B27,B28) -> 62.048819
A37: Current share price | B37: =WACC!C5 -> 75
A38: Implied upside/(downside) vs blended midpoint | B38: =B34/B37-1 -> -0.28035255
A40: SOURCE & METHOD NOTES

Sheet IS
A1: NIKE, Inc. — Consolidated Income Statement
A5: INCOME STATEMENT
B6: FY2022A | C6: FY2023A | D6: FY2024A | E6: FY2025E | F6: FY2026E | G6: FY2027E
A7: Revenues | B7: 46710 | C7: 51217 | D7: 51362 | E7: =D7*(1+Assumptions!E7) -> 51618.81 | F7: =E7*(1+Assumptions!F7) -> 53425.468 | G7: =F7*(1+Assumptions!G7) -> 55829.614
A8: Cost of sales | B8: 25231 | C8: 28925 | D8: 28412 | E8: =E7*(1-Assumptions!E8) -> 28648.44 | F8: =F7*(1-Assumptions!F8) -> 29384.008 | G8: =G7*(1-Assumptions!G8) -> 30538.799
A9: Gross Profit | B9: =B7-B8 -> 21479 | C9: =C7-C8 -> 22292 | D9: =D7-D8 -> 22950 | E9: =E7-E8 -> 22970.37 | F9: =F7-F8 -> 24041.461 | G9: =G7-G8 -> 25290.815
A10: Gross margin % | B10: =B9/B7 -> 0.45983729 | C10: =C9/C7 -> 0.43524611 | D10: =D9/D7 -> 0.44682839 | E10: =E9/E7 -> 0.445 | F10: =F9/F7 -> 0.45 | G10: =G9/G7 -> 0.453
A11: Demand creation expense | B11: 3850 | C11: 4060 | D11: 4281 | E11: =E7*Assumptions!E9 -> 4335.98 | F11: =F7*Assumptions!F9 -> 4487.7393 | G11: =G7*Assumptions!G9 -> 4633.858
A12: Operating overhead expense | B12: 10954 | C12: 12317 | D12: 12174 | E12: =E7*Assumptions!E10 -> 12078.802 | F12: =F7*Assumptions!F10 -> 12341.283 | G12: =G7*Assumptions!G10 -> 12729.152
A13: Total Selling & Administrative Expense | B13: =B11+B12 -> 14804 | C13: =C11+C12 -> 16377 | D13: =D11+D12 -> 16455 | E13: =E11+E12 -> 16414.782 | F13: =F11+F12 -> 16829.023 | G13: =G11+G12 -> 17363.01
A15: Operating Income (EBIT) | B15: =B9-B13 -> 6675 | C15: =C9-C13 -> 5915 | D15: =D9-D13 -> 6495 | E15: =E9-E13 -> 6555.5889 | F15: =F9-F13 -> 7212.4382 | G15: =G9-G13 -> 7927.8052
A16: Interest expense (income), net | B16: 205 | C16: -7 | D16: -159 | E16: =CF!E40 -> -203.768 | F16: =CF!F40 -> -140.8369 | G16: =CF!G40 -> -123.54836
A17: Other (income) expense, net | B17: -181 | C17: -280 | D17: 62 | E17: =Assumptions!E11 -> 50 | F17: =Assumptions!F11 -> 50 | G17: =Assumptions!G11 -> 50
A19: Income Before Income Taxes | B19: =B15-B16-B17 -> 6651 | C19: =C15-C16-C17 -> 6202 | D19: =D15-D16-D17 -> 6592 | E19: =E15-E16-E17 -> 6709.3569 | F19: =F15-F16-F17 -> 7303.2751 | G19: =G15-G16-G17 -> 8001.3536
A20: Income tax expense | B20: 605 | C20: 1132 | D20: 892 | E20: =E19*Assumptions!E12 -> 1073.4971 | F20: =F19*Assumptions!F12 -> 1241.5568 | G20: =G19*Assumptions!G12 -> 1400.2369
A21: Net Income | B21: =B19-B20 -> 6046 | C21: =C19-C20 -> 5070 | D21: =D19-D20 -> 5700 | E21: =E19-E20 -> 5635.8598 | F21: =F19-F20 -> 6061.7184 | G21: =G19-G20 -> 6601.1167
A22: Diluted EPS | B22: =B21/B23 -> 3.7527155 | C22: =C21/C23 -> 3.2319755 | D22: =D21/D23 -> 3.731099 | E22: =E21/E23 -> 3.7837069 | F22: =F21/F23 -> 4.1739615 | G22: =G21/G23 -> 4.6619272
A23: Diluted weighted-avg shares outstanding | B23: 1611.1 | C23: 1568.7 | D23: 1527.7 | E23: =D23*(1+Assumptions!E32) -> 1489.5075 | F23: =E23*(1+Assumptions!F32) -> 1452.2698 | G23: =F23*(1+Assumptions!G32) -> 1415.9631
A25: Memo: EBITDA | B25: =B15+B26 -> 7399.005 | C25: =C15+C26 -> 6708.8635 | D25: =D15+D26 -> 7291.111 | E25: =E15+E26 -> 7355.6804 | F25: =F15+F26 -> 8040.533 | G25: =G15+G26 -> 8793.1643
A26: Memo: D&A | B26: =B7*0.0155 -> 724.005 | C26: =C7*0.0155 -> 793.8635 | D26: =D7*0.0155 -> 796.111 | E26: =E7*Assumptions!E24 -> 800.09155 | F26: =F7*Assumptions!F24 -> 828.09476 | G26: =G7*Assumptions!G24 -> 865.35902

Sheet BS
A1: NIKE, Inc. — Consolidated Balance Sheet
A5: BALANCE SHEET
B6: FY2022A | C6: FY2023A | D6: FY2024A | E6: FY2025E | F6: FY2026E | G6: FY2027E
A7: Cash and cash equivalents | C7: 7441 | D7: 7623 | E7: =CF!E32 -> 6129.4695 | F7: =CF!F32 -> 5723.7532 | G7: =CF!G32 -> 4938.654
A8: Short-term investments | C8: 3234 | D8: 3959 | E8: =D8+Assumptions!E29 -> 3959 | F8: =E8+Assumptions!F29 -> 3959 | G8: =F8+Assumptions!G29 -> 3959
A9: Accounts receivable, net | C9: 4142 | D9: 4453 | E9: =Assumptions!E15/365*IS!E7 -> 4454.774 | F9: =Assumptions!F15/365*IS!F7 -> 4610.6911 | G9: =Assumptions!G15/365*IS!G7 -> 4818.1722
A10: Inventories | C10: 8454 | D10: 7516 | E10: =Assumptions!E16/365*IS!E8 -> 7534.932 | F10: =Assumptions!F16/365*IS!F8 -> 7567.3883 | G10: =Assumptions!G16/365*IS!G8 -> 7697.4507
A11: Prepaid expenses and other current assets | C11: 2019 | D11: 1846 | E11: =Assumptions!E18*IS!E7 -> 1858.2772 | F11: =Assumptions!F18*IS!F7 -> 1923.3169 | G11: =Assumptions!G18*IS!G7 -> 2009.8661
A12: Total Current Assets | C12: =SUM(C7:C11) -> 25290 | D12: =SUM(D7:D11) -> 25397 | E12: =SUM(E7:E11) -> 23936.453 | F12: =SUM(F7:F11) -> 23784.149 | G12: =SUM(G7:G11) -> 23423.143
A14: Property, plant and equipment, net | C14: 4942 | D14: 4874 | E14: =D14+CF!E15*-1-IS!E26 -> 5054.6658 | F14: =E14+CF!F15*-1-IS!F26 -> 5241.655 | G14: =F14+CF!G15*-1-IS!G26 -> 5437.0586
A15: Operating lease right-of-use assets, net | C15: 3024 | D15: 2789 | E15: =D15 -> 2789 | F15: =E15 -> 2789 | G15: =F15 -> 2789
A16: Identifiable intangible assets, net | C16: 277 | D16: 280 | E16: =D16 -> 280 | F16: =E16 -> 280 | G16: =F16 -> 280
A17: Goodwill | C17: 131 | D17: 131 | E17: =D17 -> 131 | F17: =E17 -> 131 | G17: =F17 -> 131
A18: Deferred income taxes and other assets | C18: 3867 | D18: 3828 | E18: =D18 -> 3828 | F18: =E18 -> 3828 | G18: =F18 -> 3828
A19: Total Assets | B19: 40321 | C19: =C12+SUM(C14:C18) -> 37531 | D19: =D12+SUM(D14:D18) -> 37299 | E19: =E12+SUM(E14:E18) -> 36019.119 | F19: =F12+SUM(F14:F18) -> 36053.804 | G19: =G12+SUM(G14:G18) -> 35888.202
A21: Current Liabilities
A22: Current portion of long-term debt | C22: 0 | D22: 1000 | E22: =D22 -> 1000 | F22: =E22 -> 1000 | G22: =F22 -> 1000
A23: Notes payable | C23: 6 | D23: 10 | E23: =D23 -> 10 | F23: =E23 -> 10 | G23: =F23 -> 10
A28: Accounts payable | C28: 2752 | D28: 2668 | E28: =Assumptions!E17/365*IS!E8 -> 2692.1684 | F28: =Assumptions!F17/365*IS!F8 -> 2761.2917 | G28: =Assumptions!G17/365*IS!G8 -> 2869.8104
A29: Accrued liabilities | C29: 5862 | D29: 5618 | E29: =Assumptions!E19*IS!E7 -> 5626.4503 | F29: =Assumptions!F19*IS!F7 -> 5823.3761 | G29: =Assumptions!G19*IS!G7 -> 6085.428
A30: Income taxes payable | C30: 240 | D30: 291 | E30: =Assumptions!E20*IS!E20 -> 349.96005 | F30: =Assumptions!F20*IS!F20 -> 404.74751 | G30: =Assumptions!G20*IS!G20 -> 456.47722
A31: Operating lease liabilities (current) | C31: 549 | D31: 520 | E31: =D31 -> 520 | F31: =E31 -> 520 | G31: =F31 -> 520
A32: Total Current Liabilities | C32: =C22+C23+SUM(C28:C31) -> 9409 | D32: =D22+D23+SUM(D28:D31) -> 10107 | E32: =E22+E23+SUM(E28:E31) -> 10198.579 | F32: =F22+F23+SUM(F28:F31) -> 10519.415 | G32: =G22+G23+SUM(G28:G31) -> 10941.716
A34: Long-term debt | C34: 8927 | D34: 7931 | E34: =D34-Assumptions!E28 -> 6931 | F34: =E34-Assumptions!F28 -> 6931 | G34: =F34-Assumptions!G28 -> 6431
A35: Operating lease liabilities (non-current) | C35: 2873 | D35: 2663 | E35: =D35 -> 2663 | F35: =E35 -> 2663 | G35: =F35 -> 2663
A36: Deferred income taxes and other liabilities | C36: 2318 | D36: 2167 | E36: =D36 -> 2167 | F36: =E36 -> 2167 | G36: =F36 -> 2167
A37: Total Liabilities | B37: 25040 | C37: =C32+C34+C35+C36 -> 23527 | D37: =D32+D34+D35+D36 -> 22868 | E37: =E32+E34+E35+E36 -> 21959.579 | F37: =F32+F34+F35+F36 -> 22280.415 | G37: =G32+G34+G35+G36 -> 22202.716
A39: Shareholders' Equity
A40: Common stock (Class A and B) | C40: 3 | D40: 3 | E40: =D40 -> 3 | F40: =E40 -> 3 | G40: =F40 -> 3
A41: Capital in excess of stated value | C41: 12416 | D41: 13010 | E41: =D41+Assumptions!E25 -> 13810 | F41: =E41+Assumptions!F25 -> 14650 | G41: =F41+Assumptions!G25 -> 15530
A42: Accumulated other comprehensive income (loss) | C42: -1598 | D42: -1241 | E42: =D42 -> -1241 | F42: =E42 -> -1241 | G42: =F42 -> -1241
A43: Retained earnings | C43: 3183 | D43: 2659 | E43: =D43+IS!E21-CF!E23*-1-Assumptions!E26 -> 1487.5398 | F43: =E43+IS!F21-CF!F23*-1-Assumptions!F26 -> 361.38913 | G43: =F43+IS!G21-CF!G23*-1-Assumptions!G26 -> -606.51397
A44: Total Shareholders' Equity | B44: 15281 | C44: =SUM(C40:C43) -> 14004 | D44: =SUM(D40:D43) -> 14431 | E44: =SUM(E40:E43) -> 14059.54 | F44: =SUM(F40:F43) -> 13773.389 | G44: =SUM(G40:G43) -> 13685.486
A45: Total Liabilities and Shareholders' Equity | B45: =B37+B44 -> 40321 | C45: =C37+C44 -> 37531 | D45: =D37+D44 -> 37299 | E45: =E37+E44 -> 36019.119 | F45: =F37+F44 -> 36053.804 | G45: =G37+G44 -> 35888.202
A47: CHECK: Total Assets less Total Liabilities & Equity | B47: =B19-B45 -> 0 | C47: =C19-C45 -> 0 | D47: =D19-D45 -> 0 | E47: =E19-E45 -> 0 | F47: =F19-F45 -> 0 | G47: =G19-G45 -> 0

Sheet CF
A1: NIKE, Inc. — Consolidated Cash Flow Statement & Supporting Schedules
A5: CASH FLOW STATEMENT
B6: FY2022A | C6: FY2023A | D6: FY2024A | E6: FY2025E | F6: FY2026E | G6: FY2027E
A7: Cash Provided by Operations
A8: Net income | B8: 6046 | C8: 5070 | D8: 5700 | E8: =IS!E21 -> 5635.8598 | F8: =IS!F21 -> 6061.7184 | G8: =IS!G21 -> 6601.1167
A9: Depreciation & amortization | B9: =IS!B26 -> 724.005 | C9: =IS!C26 -> 793.8635 | D9: =IS!D26 -> 796.111 | E9: =IS!E26 -> 800.09155 | F9: =IS!F26 -> 828.09476 | G9: =IS!G26 -> 865.35902
A10: Stock-based comp. & other non-cash | B10: =1515-B9 -> 790.995 | C10: =1732-C9 -> 938.1365 | D10: =1466-D9 -> 669.889 | E10: =Assumptions!E25 -> 800 | F10: =Assumptions!F25 -> 840 | G10: =Assumptions!G25 -> 880
A11: Changes in working capital | B11: -2363 | C11: -961 | D11: 260 | E11: =E47 -> 58.595554 | F11: =F47 -> 67.423455 | G11: =G47 -> -1.7924307
A12: Cash Provided by Operations | B12: =SUM(B8:B11) -> 5198 | C12: =SUM(C8:C11) -> 5841 | D12: =SUM(D8:D11) -> 7426 | E12: =SUM(E8:E11) -> 7294.5469 | F12: =SUM(F8:F11) -> 7797.2366 | G12: =SUM(G8:G11) -> 8344.6833
A14: Cash Used to Invest
A15: Capital expenditures | B15: -757 | C15: -942 | D15: -948 | E15: =-IS!E7*Assumptions!E23 -> -980.75739 | F15: =-IS!F7*Assumptions!F23 -> -1015.0839 | G15: =-IS!G7*Assumptions!G23 -> -1060.7627
A16: Net (purchases) sales of short-term investments | B16: 1846 | C16: -858 | D16: -728 | E16: =-Assumptions!E29 -> 0 | F16: =-Assumptions!F29 -> 0 | G16: =-Assumptions!G29 -> 0
A17: Other investing activities | B17: -384 | C17: 155 | D17: 148 | E17: 0 | F17: 0 | G17: 0
A18: Cash Used to Invest | B18: =SUM(B15:B17) -> 705 | C18: =SUM(C15:C17) -> -1645 | D18: =SUM(D15:D17) -> -1528 | E18: =SUM(E15:E17) -> -980.75739 | F18: =SUM(F15:F17) -> -1015.0839 | G18: =SUM(G15:G17) -> -1060.7627
A20: Cash Used to Finance
A22: Net repurchases of common stock | B22: -4034 | C22: -4756 | D22: -4260 | E22: =-Assumptions!E26 -> -4400 | F22: =-Assumptions!F26 -> -4600 | G22: =-Assumptions!G26 -> -4800
A23: Dividends — common and preferred | B23: -1845 | C23: -2018 | D23: -2229 | E23: =D23*(1+Assumptions!E27) -> -2407.32 | F23: =E23*(1+Assumptions!F27) -> -2587.869 | G23: =F23*(1+Assumptions!G27) -> -2769.0198
A24: Net change in debt & other financing | B24: -2254 | C24: 2246 | D24: 774 | E24: =-Assumptions!E28 -> -1000 | F24: =-Assumptions!F28 -> 0 | G24: =-Assumptions!G28 -> -500
A25: Cash Used to Finance | B25: =SUM(B22:B24) -> -8133 | C25: =SUM(C22:C24) -> -4528 | D25: =SUM(D22:D24) -> -5715 | E25: =SUM(E22:E24) -> -7807.32 | F25: =SUM(F22:F24) -> -7187.869 | G25: =SUM(G22:G24) -> -8069.0198
A27: Effect of exchange rate changes | B27: -125 | C27: -74 | D27: -1 | E27: 0 | F27: 0 | G27: 0
A29: Net Increase (Decrease) in Cash | B29: =B12+B18+B25+B27 -> -2355 | C29: =C12+C18+C25+C27 -> -406 | D29: =D12+D18+D25+D27 -> 182 | E29: =E12+E18+E25+E27 -> -1493.5305 | F29: =F12+F18+F25+F27 -> -405.71633 | G29: =G12+G18+G25+G27 -> -785.09918
A31: Cash and cash equivalents, beginning of year | B31: 10202 | C31: 7847 | D31: 7441 | E31: =BS!D7 -> 7623 | F31: =BS!E7 -> 6129.4695 | G31: =BS!F7 -> 5723.7532
A32: Cash and Cash Equivalents, End of Year | B32: =B31+B29 -> 7847 | C32: =C31+C29 -> 7441 | D32: =D31+D29 -> 7623 | E32: =E31+E29 -> 6129.4695 | F32: =F31+F29 -> 5723.7532 | G32: =G31+G29 -> 4938.654
A35: DEBT & INTEREST SCHEDULE
B36: FY2022A | C36: FY2023A | D36: FY2024A | E36: FY2025E | F36: FY2026E | G36: FY2027E
A37: Total debt — beginning of year | D37: =C39 -> 8933 | E37: =D39 -> 8941 | F37: =E39 -> 7941 | G37: =F39 -> 7941
A38: Less: scheduled repayment | E38: =-Assumptions!E28 -> -1000 | F38: =-Assumptions!F28 -> 0 | G38: =-Assumptions!G28 -> -500
A39: Total debt — end of year | C39: =BS!C22+BS!C23+BS!C34 -> 8933 | D39: =BS!D22+BS!D23+BS!D34 -> 8941 | E39: =E37+E38 -> 7941 | F39: =F37+F38 -> 7941 | G39: =G37+G38 -> 7441
A40: Net interest expense (income) | E40: =E41+E42 -> -203.768 | F40: =F41+F42 -> -140.8369 | G40: =G41+G42 -> -123.54836
A41: Interest expense on average debt | E41: =AVERAGE(E37,E39)*Assumptions!E31 -> 236.348 | F41: =AVERAGE(F37,F39)*Assumptions!F31 -> 222.348 | G41: =AVERAGE(G37,G39)*Assumptions!G31 -> 215.348
A42: Interest income on average cash & ST investments | E42: =-AVERAGE(BS!D7+BS!D8,BS!D7+BS!D8)*Assumptions!E30 -> -440.116 | F42: =-AVERAGE(BS!E7+BS!E8,BS!E7+BS!E8)*Assumptions!F30 -> -363.1849 | G42: =-AVERAGE(BS!F7+BS!F8,BS!F7+BS!F8)*Assumptions!G30 -> -338.89636
A45: WORKING CAPITAL SCHEDULE (increase in net WC = use of cash)
B46: FY2022A | C46: FY2023A | D46: FY2024A | E46: FY2025E | F46: FY2026E | G46: FY2027E
A47: Change in net working capital | E47: =-(E48-D48) -> 58.595554 | F47: =-(F48-E48) -> 67.423455 | G47: =-(G48-F48) -> -1.7924307
A48: Net working capital (operating) | C48: =(BS!C9+BS!C10+BS!C11)-(BS!C28+BS!C29+BS!C30) -> 5761 | D48: =(BS!D9+BS!D10+BS!D11)-(BS!D28+BS!D29+BS!D30) -> 5238 | E48: =(BS!E9+BS!E10+BS!E11)-(BS!E28+BS!E29+BS!E30) -> 5179.4044 | F48: =(BS!F9+BS!F10+BS!F11)-(BS!F28+BS!F29+BS!F30) -> 5111.981 | G48: =(BS!G9+BS!G10+BS!G11)-(BS!G28+BS!G29+BS!G30) -> 5113.7734

Sheet Summary
A1: NIKE, Inc. — Model Output Summary
A5: KEY METRICS
B6: FY2022A | C6: FY2023A | D6: FY2024A | E6: FY2025E | F6: FY2026E | G6: FY2027E
A7: Revenue | B7: =IS!B7 -> 46710 | C7: =IS!C7 -> 51217 | D7: =IS!D7 -> 51362 | E7: =IS!E7 -> 51618.81 | F7: =IS!F7 -> 53425.468 | G7: =IS!G7 -> 55829.614
A8: Growth % | C8: =IF(B7=0,"",C7/B7-1) -> 0.096488975 | D8: =IF(C7=0,"",D7/C7-1) -> 0.0028310912 | E8: =IF(D7=0,"",E7/D7-1) -> 0.005 | F8: =IF(E7=0,"",F7/E7-1) -> 0.035 | G8: =IF(F7=0,"",G7/F7-1) -> 0.045
A9: Gross profit | B9: =IS!B9 -> 21479 | C9: =IS!C9 -> 22292 | D9: =IS!D9 -> 22950 | E9: =IS!E9 -> 22970.37 | F9: =IS!F9 -> 24041.461 | G9: =IS!G9 -> 25290.815
A10: Gross margin % | B10: =B9/B7 -> 0.45983729 | C10: =C9/C7 -> 0.43524611 | D10: =D9/D7 -> 0.44682839 | E10: =E9/E7 -> 0.445 | F10: =F9/F7 -> 0.45 | G10: =G9/G7 -> 0.453
A11: EBIT | B11: =IS!B15 -> 6675 | C11: =IS!C15 -> 5915 | D11: =IS!D15 -> 6495 | E11: =IS!E15 -> 6555.5889 | F11: =IS!F15 -> 7212.4382 | G11: =IS!G15 -> 7927.8052
A12: EBIT margin % | B12: =B11/B7 -> 0.14290302 | C12: =C11/C7 -> 0.115489 | D12: =D11/D7 -> 0.12645536 | E12: =E11/E7 -> 0.127 | F12: =F11/F7 -> 0.135 | G12: =G11/G7 -> 0.142
A13: EBITDA | B13: =IS!B25 -> 7399.005 | C13: =IS!C25 -> 6708.8635 | D13: =IS!D25 -> 7291.111 | E13: =IS!E25 -> 7355.6804 | F13: =IS!F25 -> 8040.533 | G13: =IS!G25 -> 8793.1643
A14: Net income | B14: =IS!B21 -> 6046 | C14: =IS!C21 -> 5070 | D14: =IS!D21 -> 5700 | E14: =IS!E21 -> 5635.8598 | F14: =IS!F21 -> 6061.7184 | G14: =IS!G21 -> 6601.1167
A15: Net margin % | B15: =B14/B7 -> 0.12943695 | C15: =C14/C7 -> 0.09899057 | D15: =D14/D7 -> 0.11097699 | E15: =E14/E7 -> 0.10918229 | F15: =F14/F7 -> 0.11346121 | G15: =G14/G7 -> 0.11823683
A16: Diluted EPS | B16: =IS!B22 -> 3.7527155 | C16: =IS!C22 -> 3.2319755 | D16: =IS!D22 -> 3.731099 | E16: =IS!E22 -> 3.7837069 | F16: =IS!F22 -> 4.1739615 | G16: =IS!G22 -> 4.6619272
A19: UNLEVERED FREE CASH FLOW (the input to a DCF)
B20: FY2022A | C20: FY2023A | D20: FY2024A | E20: FY2025E | F20: FY2026E | G20: FY2027E
A21: EBIT | E21: =IS!E15 -> 6555.5889 | F21: =IS!F15 -> 7212.4382 | G21: =IS!G15 -> 7927.8052
A22: Less: taxes on EBIT | E22: =-E21*Assumptions!E12 -> -1048.8942 | F22: =-F21*Assumptions!F12 -> -1226.1145 | G22: =-G21*Assumptions!G12 -> -1387.3659
A23: NOPAT | E23: =E21+E22 -> 5506.6947 | F23: =F21+F22 -> 5986.3237 | G23: =G21+G22 -> 6540.4393
A24: Plus: D&A | E24: =IS!E26 -> 800.09155 | F24: =IS!F26 -> 828.09476 | G24: =IS!G26 -> 865.35902
A25: Less: capital expenditures | E25: =CF!E15 -> -980.75739 | F25: =CF!F15 -> -1015.0839 | G25: =CF!G15 -> -1060.7627
A26: Less: increase in working capital | E26: =CF!E47 -> 58.595554 | F26: =CF!F47 -> 67.423455 | G26: =CF!G47 -> -1.7924307
A27: Unlevered Free Cash Flow | E27: =E23+E24+E25+E26 -> 5384.6244 | F27: =F23+F24+F25+F26 -> 5866.758 | G27: =G23+G24+G25+G26 -> 6343.2432
A29: BALANCE SHEET INTEGRITY CHECK (must be zero in every column)
B30: FY2022A | C30: FY2023A | D30: FY2024A | E30: FY2025E | F30: FY2026E | G30: FY2027E
A31: Assets less Liabilities & Equity | B31: =BS!B47 -> 0 | C31: =BS!C47 -> 0 | D31: =BS!D47 -> 0 | E31: =BS!E47 -> 0 | F31: =BS!F47 -> 0 | G31: =BS!G47 -> 0
A33: Note: unlevered FCF above is calculated before interest, so it is the correct numerator to discount at WACC in a DCF.

Sheet WACC
A1: NIKE, Inc. — Cost of Capital (CAPM → WACC)
A4: MARKET DATA
A5: Nike share price ($) | C5: 75
A6: Diluted shares outstanding (mm) | C6: 1527.7
A7: Market capitalisation (equity value) | C7: =C5*C6 -> 114577.5
A8: Total debt (incl. current portion + notes payable) | C8: =BS!D22+BS!D23+BS!D34 -> 8941
A9: Less: cash and short-term investments | C9: =-(BS!D7+BS!D8) -> -11582
A10: Net debt / (net cash) | C10: =C8+C9 -> -2641
A11: Enterprise value | C11: =C7+C10 -> 111936.5
A13: COST OF EQUITY — CAPM
A14: Risk-free rate (US 10-Yr Treasury, Aug 2026) | C14: 0.0473
A15: Levered beta (5-yr monthly) | C15: 1.08
A16: Equity risk premium (Damodaran US) | C16: 0.0445
A17: Cost of equity = Rf + β × ERP | C17: =C14+C15*C16 -> 0.09536
A19: COST OF DEBT
A20: Pre-tax cost of debt | C20: 0.05
A21: Marginal tax rate | C21: 0.175
A22: After-tax cost of debt = Kd × (1 − t) | C22: =C20*(1-C21) -> 0.04125
A24: WACC
A25: Equity weight E / (D+E) | C25: =C7/(C7+C8) -> 0.92761408
A26: Debt weight D / (D+E) | C26: =C8/(C7+C8) -> 0.072385918
A27: WACC = We × Ke + Wd × Kd × (1 − t) | C27: =C25*C17+C26*C22 -> 0.091443198

Sheet DCF
A1: NIKE, Inc. — Discounted Cash Flow Valuation
A4: FREE CASH FLOW BUILD
C5: FY2025E | D5: FY2026E | E5: FY2027E | F5: FY2028E | G5: FY2029E
A6: EBIT | C6: =Summary!E21 -> 6555.5889 | D6: =Summary!F21 -> 7212.4382 | E6: =Summary!G21 -> 7927.8052
A7: Less: taxes on EBIT | C7: =Summary!E22 -> -1048.8942 | D7: =Summary!F22 -> -1226.1145 | E7: =Summary!G22 -> -1387.3659
A8: NOPAT | C8: =C6+C7 -> 5506.6947 | D8: =D6+D7 -> 5986.3237 | E8: =E6+E7 -> 6540.4393
A9: Plus: D&A | C9: =Summary!E24 -> 800.09155 | D9: =Summary!F24 -> 828.09476 | E9: =Summary!G24 -> 865.35902
A10: Less: capital expenditures | C10: =Summary!E25 -> -980.75739 | D10: =Summary!F25 -> -1015.0839 | E10: =Summary!G25 -> -1060.7627
A11: Less: increase in working capital | C11: =Summary!E26 -> 58.595554 | D11: =Summary!F26 -> 67.423455 | E11: =Summary!G26 -> -1.7924307
A12: Unlevered Free Cash Flow | C12: =C8+C9+C10+C11 -> 5384.6244 | D12: =D8+D9+D10+D11 -> 5866.758 | E12: =E8+E9+E10+E11 -> 6343.2432 | F12: =E12*(1+F15) -> 6596.973 | G12: =F12*(1+G15) -> 6860.8519
A13: FCF growth % | D13: =D12/C12-1 -> 0.089538962 | E13: =E12/D12-1 -> 0.081217804 | F13: =F12/E12-1 -> 0.04 | G13: =G12/F12-1 -> 0.04
A15: Stub-year FCF growth (FY28–FY29) | F15: 0.04 | G15: 0.04
A17: DISCOUNTING
A18: WACC (from WACC tab) | C18: =WACC!C27 -> 0.091443198
A19: Terminal growth rate (g) | C19: 0.025
A20: Discount period (years) | C20: 1 | D20: 2 | E20: 3 | F20: 4 | G20: 5
A21: Discount factor = 1 / (1+WACC)^n | C21: =1/(1+$C$18)^C20 -> 0.91621809 | D21: =1/(1+$C$18)^D20 -> 0.83945558 | E21: =1/(1+$C$18)^E20 -> 0.76912439 | F21: =1/(1+$C$18)^F20 -> 0.70468568 | G21: =1/(1+$C$18)^G20 -> 0.64564577
A22: PV of unlevered FCF | C22: =C12*C21 -> 4933.4902 | D22: =D12*D21 -> 4924.8828 | E22: =E12*E21 -> 4878.7431 | F22: =F12*F21 -> 4648.7924 | G22: =G12*G21 -> 4429.68
A24: TERMINAL VALUE (Gordon Growth)
A25: Final-year FCF (FY2029E) | C25: =G12 -> 6860.8519
A26: Terminal value = FCF × (1+g) / (WACC − g) | C26: =C25*(1+C19)/(C18-C19) -> 105840.38
A27: PV of terminal value | C27: =C26*G21 -> 68335.392
A29: VALUATION BRIDGE
A30: Sum of PV of forecast FCF (FY25–FY29) | C30: =SUM(C22:G22) -> 23815.589
A31: Plus: PV of terminal value | C31: =C27 -> 68335.392
A32: Enterprise Value | C32: =C30+C31 -> 92150.98
A33: TV as % of EV | C33: =C31/C32 -> 0.74155903
A34: Less: net debt / plus net cash | C34: =-WACC!C10 -> 2641
A35: Implied Equity Value | C35: =C32+C34 -> 94791.98
A36: Diluted shares outstanding (mm) | C36: =WACC!C6 -> 1527.7
A37: Implied Share Price | C37: =C35/C36 -> 62.048819
A38: Current share price | C38: =WACC!C5 -> 75
A39: Implied upside / (downside) | C39: =C37/C38-1 -> -0.17268242
A42: SENSITIVITY — IMPLIED SHARE PRICE: WACC (across) vs TERMINAL GROWTH (down)
B43: g \ WACC | C43: =$C$18+-0.01 -> 0.081443198 | D43: =$C$18+-0.005 -> 0.086443198 | E43: =$C$18+0 -> 0.091443198 | F43: =$C$18+0.005 -> 0.096443198 | G43: =$C$18+0.01 -> 0.1014432
B44: =$C$19+-0.01 -> 0.015 | C44: =(($C$12/(1+C$43)^$C$20+$D$12/(1+C$43)^$D$20+$E$12/(1+C$43)^$E$20+$F$12/(1+C$43)^$F$20+$G$12/(1+C$43)^$G$20+($G$12*(1+$B44)/(C$43-$B44))/(1+C$43)^$G$20)+$C$34)/$C$36 -> 64.128436 | D44: =(($C$12/(1+D$43)^$C$20+$D$12/(1+D$43)^$D$20+$E$12/(1+D$43)^$E$20+$F$12/(1+D$43)^$F$20+$G$12/(1+D$43)^$G$20+($G$12*(1+$B44)/(D$43-$B44))/(1+D$43)^$G$20)+$C$34)/$C$36 -> 59.681768 | E44: =(($C$12/(1+E$43)^$C$20+$D$12/(1+E$43)^$D$20+$E$12/(1+E$43)^$E$20+$F$12/(1+E$43)^$F$20+$G$12/(1+E$43)^$G$20+($G$12*(1+$B44)/(E$43-$B44))/(1+E$43)^$G$20)+$C$34)/$C$36 -> 55.817987 | F44: =(($C$12/(1+F$43)^$C$20+$D$12/(1+F$43)^$D$20+$E$12/(1+F$43)^$E$20+$F$12/(1+F$43)^$F$20+$G$12/(1+F$43)^$G$20+($G$12*(1+$B44)/(F$43-$B44))/(1+F$43)^$G$20)+$C$34)/$C$36 -> 52.429713 | G44: =(($C$12/(1+G$43)^$C$20+$D$12/(1+G$43)^$D$20+$E$12/(1+G$43)^$E$20+$F$12/(1+G$43)^$F$20+$G$12/(1+G$43)^$G$20+($G$12*(1+$B44)/(G$43-$B44))/(1+G$43)^$G$20)+$C$34)/$C$36 -> 49.434412
B45: =$C$19+-0.005 -> 0.02 | C45: =(($C$12/(1+C$43)^$C$20+$D$12/(1+C$43)^$D$20+$E$12/(1+C$43)^$E$20+$F$12/(1+C$43)^$F$20+$G$12/(1+C$43)^$G$20+($G$12*(1+$B45)/(C$43-$B45))/(1+C$43)^$G$20)+$C$34)/$C$36 -> 68.149775 | D45: =(($C$12/(1+D$43)^$C$20+$D$12/(1+D$43)^$D$20+$E$12/(1+D$43)^$E$20+$F$12/(1+D$43)^$F$20+$G$12/(1+D$43)^$G$20+($G$12*(1+$B45)/(D$43-$B45))/(1+D$43)^$G$20)+$C$34)/$C$36 -> 63.077008 | E45: =(($C$12/(1+E$43)^$C$20+$D$12/(1+E$43)^$D$20+$E$12/(1+E$43)^$E$20+$F$12/(1+E$43)^$F$20+$G$12/(1+E$43)^$G$20+($G$12*(1+$B45)/(E$43-$B45))/(1+E$43)^$G$20)+$C$34)/$C$36 -> 58.715368 | F45: =(($C$12/(1+F$43)^$C$20+$D$12/(1+F$43)^$D$20+$E$12/(1+F$43)^$E$20+$F$12/(1+F$43)^$F$20+$G$12/(1+F$43)^$G$20+($G$12*(1+$B45)/(F$43-$B45))/(1+F$43)^$G$20)+$C$34)/$C$36 -> 54.925294 | G45: =(($C$12/(1+G$43)^$C$20+$D$12/(1+G$43)^$D$20+$E$12/(1+G$43)^$E$20+$F$12/(1+G$43)^$F$20+$G$12/(1+G$43)^$G$20+($G$12*(1+$B45)/(G$43-$B45))/(1+G$43)^$G$20)+$C$34)/$C$36 -> 51.601497
B46: =$C$19+0 -> 0.025 | C46: =(($C$12/(1+C$43)^$C$20+$D$12/(1+C$43)^$D$20+$E$12/(1+C$43)^$E$20+$F$12/(1+C$43)^$F$20+$G$12/(1+C$43)^$G$20+($G$12*(1+$B46)/(C$43-$B46))/(1+C$43)^$G$20)+$C$34)/$C$36 -> 72.883573 | D46: =(($C$12/(1+D$43)^$C$20+$D$12/(1+D$43)^$D$20+$E$12/(1+D$43)^$E$20+$F$12/(1+D$43)^$F$20+$G$12/(1+D$43)^$G$20+($G$12*(1+$B46)/(D$43-$B46))/(1+D$43)^$G$20)+$C$34)/$C$36 -> 67.02483 | E46: =(($C$12/(1+E$43)^$C$20+$D$12/(1+E$43)^$D$20+$E$12/(1+E$43)^$E$20+$F$12/(1+E$43)^$F$20+$G$12/(1+E$43)^$G$20+($G$12*(1+$B46)/(E$43-$B46))/(1+E$43)^$G$20)+$C$34)/$C$36 -> 62.048819 | F46: =(($C$12/(1+F$43)^$C$20+$D$12/(1+F$43)^$D$20+$E$12/(1+F$43)^$E$20+$F$12/(1+F$43)^$F$20+$G$12/(1+F$43)^$G$20+($G$12*(1+$B46)/(F$43-$B46))/(1+F$43)^$G$20)+$C$34)/$C$36 -> 57.770186 | G46: =(($C$12/(1+G$43)^$C$20+$D$12/(1+G$43)^$D$20+$E$12/(1+G$43)^$E$20+$F$12/(1+G$43)^$F$20+$G$12/(1+G$43)^$G$20+($G$12*(1+$B46)/(G$43-$B46))/(1+G$43)^$G$20)+$C$34)/$C$36 -> 54.052071
B47: =$C$19+0.005 -> 0.03 | C47: =(($C$12/(1+C$43)^$C$20+$D$12/(1+C$43)^$D$20+$E$12/(1+C$43)^$E$20+$F$12/(1+C$43)^$F$20+$G$12/(1+C$43)^$G$20+($G$12*(1+$B47)/(C$43-$B47))/(1+C$43)^$G$20)+$C$34)/$C$36 -> 78.53757 | D47: =(($C$12/(1+D$43)^$C$20+$D$12/(1+D$43)^$D$20+$E$12/(1+D$43)^$E$20+$F$12/(1+D$43)^$F$20+$G$12/(1+D$43)^$G$20+($G$12*(1+$B47)/(D$43-$B47))/(1+D$43)^$G$20)+$C$34)/$C$36 -> 71.672084 | E47: =(($C$12/(1+E$43)^$C$20+$D$12/(1+E$43)^$D$20+$E$12/(1+E$43)^$E$20+$F$12/(1+E$43)^$F$20+$G$12/(1+E$43)^$G$20+($G$12*(1+$B47)/(E$43-$B47))/(1+E$43)^$G$20)+$C$34)/$C$36 -> 65.924795 | F47: =(($C$12/(1+F$43)^$C$20+$D$12/(1+F$43)^$D$20+$E$12/(1+F$43)^$E$20+$F$12/(1+F$43)^$F$20+$G$12/(1+F$43)^$G$20+($G$12*(1+$B47)/(F$43-$B47))/(1+F$43)^$G$20)+$C$34)/$C$36 -> 61.043246 | G47: =(($C$12/(1+G$43)^$C$20+$D$12/(1+G$43)^$D$20+$E$12/(1+G$43)^$E$20+$F$12/(1+G$43)^$F$20+$G$12/(1+G$43)^$G$20+($G$12*(1+$B47)/(G$43-$B47))/(1+G$43)^$G$20)+$C$34)/$C$36 -> 56.845655
B48: =$C$19+0.01 -> 0.035 | C48: =(($C$12/(1+C$43)^$C$20+$D$12/(1+C$43)^$D$20+$E$12/(1+C$43)^$E$20+$F$12/(1+C$43)^$F$20+$G$12/(1+C$43)^$G$20+($G$12*(1+$B48)/(C$43-$B48))/(1+C$43)^$G$20)+$C$34)/$C$36 -> 85.408967 | D48: =(($C$12/(1+D$43)^$C$20+$D$12/(1+D$43)^$D$20+$E$12/(1+D$43)^$E$20+$F$12/(1+D$43)^$F$20+$G$12/(1+D$43)^$G$20+($G$12*(1+$B48)/(D$43-$B48))/(1+D$43)^$G$20)+$C$34)/$C$36 -> 77.222714 | E48: =(($C$12/(1+E$43)^$C$20+$D$12/(1+E$43)^$D$20+$E$12/(1+E$43)^$E$20+$F$12/(1+E$43)^$F$20+$G$12/(1+E$43)^$G$20+($G$12*(1+$B48)/(E$43-$B48))/(1+E$43)^$G$20)+$C$34)/$C$36 -> 70.487475 | F48: =(($C$12/(1+F$43)^$C$20+$D$12/(1+F$43)^$D$20+$E$12/(1+F$43)^$E$20+$F$12/(1+F$43)^$F$20+$G$12/(1+F$43)^$G$20+($G$12*(1+$B48)/(F$43-$B48))/(1+F$43)^$G$20)+$C$34)/$C$36 -> 64.849003 | G48: =(($C$12/(1+G$43)^$C$20+$D$12/(1+G$43)^$D$20+$E$12/(1+G$43)^$E$20+$F$12/(1+G$43)^$F$20+$G$12/(1+G$43)^$G$20+($G$12*(1+$B48)/(G$43-$B48))/(1+G$43)^$G$20)+$C$34)/$C$36 -> 60.059687

Sheet Comps
A1: Trading Comparables — Athletic Footwear & Apparel
A5: Company | B5: Ticker | C5: Share Price | D5: Diluted Shares (M) | E5: Market Cap | F5: Net Debt | G5: Enterprise Value | H5: LTM Revenue | I5: LTM EBITDA | J5: EV / Revenue | K5: EV / EBITDA
A6: Lululemon Athletica | B6: NASDAQ: LULU | C6: 120.8 | D6: 108.4 | E6: =C6*D6 -> 13094.72 | F6: 630 | G6: =E6+F6 -> 13724.72 | H6: 11200 | I6: 2600 | J6: =G6/H6 -> 1.2254214 | K6: =G6/I6 -> 5.2787385
A7: Deckers Outdoor | B7: NYSE: DECK | C7: 91.5 | D7: 151.2 | E7: =C7*D7 -> 13834.8 | F7: -1130 | G7: =E7+F7 -> 12704.8 | H7: 5350 | I7: 1360 | J7: =G7/H7 -> 2.374729 | K7: =G7/I7 -> 9.3417647
A8: Skechers U.S.A. | B8: NYSE: SKX | C8: 63.1 | D8: 150.3 | E8: =C8*D8 -> 9483.93 | F8: -120 | G8: =E8+F8 -> 9363.93 | H8: 9410 | I8: 1180 | J8: =G8/H8 -> 0.99510414 | K8: =G8/I8 -> 7.9355339
A9: Under Armour | B9: NYSE: UAA | C9: 5.35 | D9: 426 | E9: =C9*D9 -> 2279.1 | F9: 450 | G9: =E9+F9 -> 2729.1 | H9: 5180 | I9: 310 | J9: =G9/H9 -> 0.52685328 | K9: =G9/I9 -> 8.8035484
A10: Adidas AG | B10: XETRA: ADS | C10: 153.1 | D10: 174 | E10: =C10*D10 -> 26639.4 | F10: 3250 | G10: =E10+F10 -> 29889.4 | H10: 26040 | I10: 2850 | J10: =G10/H10 -> 1.1478264 | K10: =G10/I10 -> 10.487509
A11: Puma SE | B11: XETRA: PUM | C11: 27.8 | D11: 147.2 | E11: =C11*D11 -> 4092.16 | F11: 2450 | G11: =E11+F11 -> 6542.16 | H11: 7900 | I11: 640 | J11: =G11/H11 -> 0.82812152 | K11: =G11/I11 -> 10.222125
A12: ASICS Corporation | B12: TYO: 7936 | C12: 175.8 | D12: 121.7 | E12: =C12*D12 -> 21394.86 | F12: 300 | G12: =E12+F12 -> 21694.86 | H12: 4110 | I12: 750 | J12: =G12/H12 -> 5.2785547 | K12: =G12/I12 -> 28.92648
A13: Anta Sports Products | B13: HKEX: 2020 | C13: 10.23 | D13: 2590 | E13: =C13*D13 -> 26495.7 | F13: -800 | G13: =E13+F13 -> 25695.7 | H13: 9500 | I13: 1900 | J13: =G13/H13 -> 2.7048105 | K13: =G13/I13 -> 13.524053
A14: On Holding AG | B14: NYSE: ONON | C14: 27.43 | D14: 334.2 | E14: =C14*D14 -> 9167.106 | F14: 100 | G14: =E14+F14 -> 9267.106 | H14: 3960 | I14: 715 | J14: =G14/H14 -> 2.3401783 | K14: =G14/I14 -> 12.960987
A15: V.F. Corporation | B15: NYSE: VFC | C15: 13.17 | D15: 393.1 | E15: =C15*D15 -> 5177.127 | F15: 4280 | G15: =E15+F15 -> 9457.127 | H15: 9510 | I15: 903 | J15: =G15/H15 -> 0.99444027 | K15: =G15/I15 -> 10.473009
A17: Peer Median | J17: =MEDIAN(J6:J15) -> 1.1866239 | K17: =MEDIAN(K6:K15) -> 10.347567
A18: Peer Mean | J18: =AVERAGE(J6:J15) -> 1.841604 | K18: =AVERAGE(K6:K15) -> 11.795375
A19: Peer Low | J19: =MIN(J6:J15) -> 0.52685328 | K19: =MIN(K6:K15) -> 5.2787385
A20: Peer High | J20: =MAX(J6:J15) -> 5.2785547 | K20: =MAX(K6:K15) -> 28.92648
A23: IMPLIED NIKE VALUATION AT PEER MULTIPLES
C24: Multiple | D24: Metric | E24: Implied EV | F24: Implied Equity | G24: Implied Price
A25: Nike LTM revenue (FY2024A) | D25: =IS!D7 -> 51362
A26: Nike LTM EBITDA (FY2024A) | D26: =IS!D25 -> 7291.111
A28: EV / Revenue — peer median | C28: =J17 -> 1.1866239 | D28: =D25 -> 51362 | E28: =C28*D28 -> 60947.378 | F28: =E28-WACC!C10 -> 63588.378 | G28: =F28/WACC!C6 -> 41.623603
A29: EV / EBITDA — peer median | C29: =K17 -> 10.347567 | D29: =D26 -> 7291.111 | E29: =C29*D29 -> 75445.259 | F29: =E29-WACC!C10 -> 78086.259 | G29: =F29/WACC!C6 -> 51.113608
A30: EV / Revenue — peer low | C30: =J19 -> 0.52685328 | D30: =D25 -> 51362 | E30: =C30*D30 -> 27060.238 | F30: =E30-WACC!C10 -> 29701.238 | G30: =F30/WACC!C6 -> 19.4418
A31: EV / EBITDA — peer low | C31: =K19 -> 5.2787385 | D31: =D26 -> 7291.111 | E31: =C31*D31 -> 38487.868 | F31: =E31-WACC!C10 -> 41128.868 | G31: =F31/WACC!C6 -> 26.922084
A32: EV / Revenue — peer high | C32: =J20 -> 5.2785547 | D32: =D25 -> 51362 | E32: =C32*D32 -> 271117.13 | F32: =E32-WACC!C10 -> 273758.13 | G32: =F32/WACC!C6 -> 179.19626
A33: EV / EBITDA — peer high | C33: =K20 -> 28.92648 | D33: =D26 -> 7291.111 | E33: =C33*D33 -> 210906.18 | F33: =E33-WACC!C10 -> 213547.18 | G33: =F33/WACC!C6 -> 139.78345

Sheet Street Comps
A1: NIKE, Inc. — Street-Standard Trading Comps (LTM & Forward)
A4: TREASURY-STOCK-METHOD (TSM) DILUTED SHARES — NIKE
A5: Basic weighted-avg shares outstanding (mm) | C5: 1509
A6: Current share price ($) | C6: =WACC!C5 -> 75
A7: In-the-money options outstanding (mm) | C7: 2
A8: Weighted-avg exercise price ($) | C8: 70
A9: Proceeds from option exercise ($mm) | C9: =C7*C8 -> 140
A10: Shares repurchased from option proceeds (mm) | C10: =C9/C6 -> 1.8666667
A11: Net new shares from options (mm) | C11: =C7-C10 -> 0.13333333
A13: Unvested RSUs / PSUs outstanding (mm) | C13: 17
A14: Unrecognized comp. cost assumed as proceeds ($mm) | C14: 600
A15: Shares repurchased from RSU proceeds (mm) | C15: =C14/C6 -> 8
A16: Net new shares from RSUs (mm) | C16: =C13-C15 -> 9
A18: TSM diluted shares outstanding (mm) | C18: =C5+C11+C16 -> 1518.1333
A19: Reported GAAP diluted shares (10-K weighted avg) | C19: =WACC!C6 -> 1527.7
A20: Variance (TSM vs. reported) | C20: =C18-C19 -> -9.5666667
A22: PEER SET — LTM & NTM FINANCIALS, CALENDARIZED TO A COMMON DEC FISCAL YEAR-END
A23: Company | B23: Ticker | C23: FYE (month) | D23: Calendarization factor | E23: LTM Revenue (reported) | F23: LTM EBITDA (reported) | G23: NTM growth % (Street est.) | H23: Calendarized LTM Revenue | I23: Calendarized LTM EBITDA | J23: NTM Revenue (Street est.) | K23: NTM EBITDA (Street est.) | L23: EV (from Comps tab) | M23: EV / Cal. LTM Rev | N23: EV / Cal. LTM EBITDA | O23: EV / NTM Revenue | P23: EV / NTM EBITDA
A24: Lululemon Athletica | B24: NASDAQ: LULU | C24: Jan | D24: 0.995 | E24: =Comps!H6 -> 11200 | F24: =Comps!I6 -> 2600 | G24: 0.09 | H24: =E24*D24 -> 11144 | I24: =F24*D24 -> 2587 | J24: =H24*(1+G24) -> 12146.96 | K24: =I24*(1+G24) -> 2819.83 | L24: =Comps!G6 -> 13724.72 | M24: =L24/H24 -> 1.2315793 | N24: =L24/I24 -> 5.3052648 | O24: =L24/J24 -> 1.1298893 | P24: =L24/K24 -> 4.8672154
A25: Deckers Outdoor | B25: NYSE: DECK | C25: Mar | D25: 0.985 | E25: =Comps!H7 -> 5350 | F25: =Comps!I7 -> 1360 | G25: 0.12 | H25: =E25*D25 -> 5269.75 | I25: =F25*D25 -> 1339.6 | J25: =H25*(1+G25) -> 5902.12 | K25: =I25*(1+G25) -> 1500.352 | L25: =Comps!G7 -> 12704.8 | M25: =L25/H25 -> 2.4108924 | N25: =L25/I25 -> 9.4840251 | O25: =L25/J25 -> 2.1525825 | P25: =L25/K25 -> 8.4678795
A26: Skechers U.S.A. | B26: NYSE: SKX | C26: Dec | D26: 1 | E26: =Comps!H8 -> 9410 | F26: =Comps!I8 -> 1180 | G26: 0.05 | H26: =E26*D26 -> 9410 | I26: =F26*D26 -> 1180 | J26: =H26*(1+G26) -> 9880.5 | K26: =I26*(1+G26) -> 1239 | L26: =Comps!G8 -> 9363.93 | M26: =L26/H26 -> 0.99510414 | N26: =L26/I26 -> 7.9355339 | O26: =L26/J26 -> 0.94771823 | P26: =L26/K26 -> 7.5576513
A27: Under Armour | B27: NYSE: UAA | C27: Mar | D27: 0.985 | E27: =Comps!H9 -> 5180 | F27: =Comps!I9 -> 310 | G27: -0.02 | H27: =E27*D27 -> 5102.3 | I27: =F27*D27 -> 305.35 | J27: =H27*(1+G27) -> 5000.254 | K27: =I27*(1+G27) -> 299.243 | L27: =Comps!G9 -> 2729.1 | M27: =L27/H27 -> 0.53487643 | N27: =L27/I27 -> 8.9376126 | O27: =L27/J27 -> 0.54579227 | P27: =L27/K27 -> 9.1200128
A28: Adidas AG | B28: XETRA: ADS | C28: Dec | D28: 1 | E28: =Comps!H10 -> 26040 | F28: =Comps!I10 -> 2850 | G28: 0.08 | H28: =E28*D28 -> 26040 | I28: =F28*D28 -> 2850 | J28: =H28*(1+G28) -> 28123.2 | K28: =I28*(1+G28) -> 3078 | L28: =Comps!G10 -> 29889.4 | M28: =L28/H28 -> 1.1478264 | N28: =L28/I28 -> 10.487509 | O28: =L28/J28 -> 1.0628022 | P28: =L28/K28 -> 9.7106563
A29: Puma SE | B29: XETRA: PUM | C29: Dec | D29: 1 | E29: =Comps!H11 -> 7900 | F29: =Comps!I11 -> 640 | G29: 0.04 | H29: =E29*D29 -> 7900 | I29: =F29*D29 -> 640 | J29: =H29*(1+G29) -> 8216 | K29: =I29*(1+G29) -> 665.6 | L29: =Comps!G11 -> 6542.16 | M29: =L29/H29 -> 0.82812152 | N29: =L29/I29 -> 10.222125 | O29: =L29/J29 -> 0.79627069 | P29: =L29/K29 -> 9.8289663
A30: ASICS Corporation | B30: TYO: 7936 | C30: Dec | D30: 1 | E30: =Comps!H12 -> 4110 | F30: =Comps!I12 -> 750 | G30: 0.1 | H30: =E30*D30 -> 4110 | I30: =F30*D30 -> 750 | J30: =H30*(1+G30) -> 4521 | K30: =I30*(1+G30) -> 825 | L30: =Comps!G12 -> 21694.86 | M30: =L30/H30 -> 5.2785547 | N30: =L30/I30 -> 28.92648 | O30: =L30/J30 -> 4.7986861 | P30: =L30/K30 -> 26.2968
A31: Anta Sports Products | B31: HKEX: 2020 | C31: Dec | D31: 1 | E31: =Comps!H13 -> 9500 | F31: =Comps!I13 -> 1900 | G31: 0.11 | H31: =E31*D31 -> 9500 | I31: =F31*D31 -> 1900 | J31: =H31*(1+G31) -> 10545 | K31: =I31*(1+G31) -> 2109 | L31: =Comps!G13 -> 25695.7 | M31: =L31/H31 -> 2.7048105 | N31: =L31/I31 -> 13.524053 | O31: =L31/J31 -> 2.4367662 | P31: =L31/K31 -> 12.183831
A32: On Holding AG | B32: NYSE: ONON | C32: Dec | D32: 1 | E32: =Comps!H14 -> 3960 | F32: =Comps!I14 -> 715 | G32: 0.27 | H32: =E32*D32 -> 3960 | I32: =F32*D32 -> 715 | J32: =H32*(1+G32) -> 5029.2 | K32: =I32*(1+G32) -> 908.05 | L32: =Comps!G14 -> 9267.106 | M32: =L32/H32 -> 2.3401783 | N32: =L32/I32 -> 12.960987 | O32: =L32/J32 -> 1.8426601 | P32: =L32/K32 -> 10.205502
A33: V.F. Corporation | B33: NYSE: VFC | C33: Mar | D33: 0.985 | E33: =Comps!H15 -> 9510 | F33: =Comps!I15 -> 903 | G33: 0.02 | H33: =E33*D33 -> 9367.35 | I33: =F33*D33 -> 889.455 | J33: =H33*(1+G33) -> 9554.697 | K33: =I33*(1+G33) -> 907.2441 | L33: =Comps!G15 -> 9457.127 | M33: =L33/H33 -> 1.009584 | N33: =L33/I33 -> 10.632496 | O33: =L33/J33 -> 0.98978827 | P33: =L33/K33 -> 10.424016
A34: Peer Median | M34: =MEDIAN(M24:M33) -> 1.1897029 | N34: =MEDIAN(N24:N33) -> 10.354817 | O34: =MEDIAN(O24:O33) -> 1.0963458 | P34: =MEDIAN(P24:P33) -> 9.7698113
A35: Peer Mean | M35: =AVERAGE(M24:M33) -> 1.8481528 | N35: =AVERAGE(N24:N33) -> 11.841609 | O35: =AVERAGE(O24:O33) -> 1.6702956 | P35: =AVERAGE(P24:P33) -> 10.866253
A36: Peer Low | M36: =MIN(M24:M33) -> 0.53487643 | N36: =MIN(N24:N33) -> 5.3052648 | O36: =MIN(O24:O33) -> 0.54579227 | P36: =MIN(P24:P33) -> 4.8672154
A37: Peer High | M37: =MAX(M24:M33) -> 5.2785547 | N37: =MAX(N24:N33) -> 28.92648 | O37: =MAX(O24:O33) -> 4.7986861 | P37: =MAX(P24:P33) -> 26.2968
A39: DRIVER-BASED PREMIUM / DISCOUNT MEMO
A40: Driver | B40: Nike | C40: Peer median | D40: Nike vs. peer (pts) | E40: Sensitivity (x per pt) | F40: Premium/(discount)
A41: Revenue growth, LTM->NTM | B41: =IS!E7/IS!D7-1 -> 0.005 | C41: =AVERAGE(G24:G33) -> 0.086 | D41: =(B41-C41)*100 -> -8.1 | E41: 0.02 | F41: =D41*E41 -> -0.162
A42: EBITDA margin, NTM | B42: =IS!E25/IS!E7 -> 0.1425 | C42: =AVERAGE(K24:K33)/AVERAGE(J24:J33) -> 0.14508162 | D42: =(B42-C42)*100 -> -0.25816235 | E42: 0.03 | F42: =D42*E42 -> -0.0077448704
A43: Total suggested premium/(discount) to peer median multiple | F43: =F41+F42 -> -0.16974487
A45: CROSS-SECTOR MULTIPLE MAP
A46: Sector | B46: Members | C46: EV/NTM Revenue (median) | D46: EV/NTM EBITDA (median)
A47: Premium / Performance Athletic | B47: Lululemon; Deckers; ASICS; On | C47: =MEDIAN(O24,O25,O30,O32) -> 1.9976213 | D47: =MEDIAN(P24,P25,P30,P32) -> 9.3366907
...

Sheet Precedents
A1: Precedent Transactions — Footwear & Athletic Apparel
A5: Date | B5: Acquirer | C5: Target | D5: Deal Value (EV) | E5: Target LTM Revenue | F5: Target LTM EBITDA | G5: EV / Revenue | H5: EV / EBITDA
A6: Aug 2021 | B6: Authentic Brands Group | C6: Reebok (from Adidas) | D6: 2500 | E6: 1800 | F6: 160 | G6: =D6/E6 -> 1.3888889 | H6: =D6/F6 -> 15.625
A7: Jun 2021 | B7: Anta Sports Consortium | C7: Amer Sports (Salomon / Arc'teryx) | D7: 5200 | E7: 3100 | F7: 380 | G7: =D7/E7 -> 1.6774194 | H7: =D7/F7 -> 13.684211
A8: Nov 2020 | B8: VF Corporation | C8: Supreme | D8: 2100 | E8: 500 | F8: 140 | G8: =D8/E8 -> 4.2 | H8: =D8/F8 -> 15
A9: Jun 2019 | B9: PAI Partners | C9: Asics Europe (Onitsuka Tiger stake) | D9: 450 | E9: 320 | F9: 38 | G9: =D9/E9 -> 1.40625 | H9: =D9/F9 -> 11.842105
A10: Aug 2005 | B10: adidas-Salomon AG | C10: Reebok International | D10: 3800 | E10: 3785 | F10: 340 | G10: =D10/E10 -> 1.003963 | H10: =D10/F10 -> 11.176471
A11: Nov 2012 | B11: Apax Partners | C11: Cole Haan (from Nike) | D11: 570 | E11: 600 | F11: 60 | G11: =D11/E11 -> 0.95 | H11: =D11/F11 -> 9.5
A12: Nov 2012 | B12: Iconix Brand Group | C12: Umbro (from Nike) | D12: 225 | E12: 200 | F12: 20 | G12: =D12/E12 -> 1.125 | H12: =D12/F12 -> 11.25
A13: Jan 2024 | B13: Authentic Brands Group / Aldo Group | C13: Sperry (from Wolverine Worldwide) | D13: 130 | E13: 280 | F13: 18 | G13: =D13/E13 -> 0.46428571 | H13: =D13/F13 -> 7.2222222
A15: Median | G15: =MEDIAN(G6:G13) -> 1.2569444 | H15: =MEDIAN(H6:H13) -> 11.546053
A16: Mean | G16: =AVERAGE(G6:G13) -> 1.5269759 | H16: =AVERAGE(H6:H13) -> 11.912501
A17: Low | G17: =MIN(G6:G13) -> 0.46428571 | H17: =MIN(H6:H13) -> 7.2222222
A18: High | G18: =MAX(G6:G13) -> 4.2 | H18: =MAX(H6:H13) -> 15.625
A21: IMPLIED NIKE VALUATION AT PRECEDENT MULTIPLES
D22: Multiple | E22: Implied EV | F22: Implied Equity | G22: Implied Price
A23: EV / EBITDA — median | D23: =H15 -> 11.546053 | E23: =H15*(IS!D25) -> 84183.551 | F23: =E23-WACC!C10 -> 86824.551 | G23: =F23/WACC!C6 -> 56.833509
A24: EV / EBITDA — low | D24: =H17 -> 7.2222222 | E24: =H17*(IS!D25) -> 52658.024 | F24: =E24-WACC!C10 -> 55299.024 | G24: =F24/WACC!C6 -> 36.197568
A25: EV / EBITDA — high | D25: =H18 -> 15.625 | E25: =H18*(IS!D25) -> 113923.61 | F25: =E25-WACC!C10 -> 116564.61 | G25: =F25/WACC!C6 -> 76.30072
A26: EV / Revenue — median | D26: =G15 -> 1.2569444 | E26: =G15*(IS!D7) -> 64559.181 | F26: =E26-WACC!C10 -> 67200.181 | G26: =F26/WACC!C6 -> 43.987812

Sheet LBO
A1: NIKE, Inc. — Leveraged Buyout Analysis
A4: TRANSACTION ASSUMPTIONS
A5: Entry multiple (x LTM EBITDA) | C5: 9.5
A6: LTM EBITDA (FY2024A) | C6: =IS!D25 -> 7291.111
A7: Entry enterprise value | C7: =C5*C6 -> 69265.554
A8: Exit multiple (x EBITDA) | C8: 9
A9: Holding period (years) | C9: 5
A10: Total debt % of capitalisation | C10: 0.55
A11: Sponsor equity % of capitalisation | C11: =1-C10 -> 0.45
A12: Total debt raised | C12: =C7*C10 -> 38096.055
A13: Sponsor equity cheque | C13: =C7*C11 -> 31169.5
A15: FINANCING STRUCTURE
C16: % of Debt | D16: Amount | E16: Rate | F16: Interest
A17: Term Loan B (SOFR + 275bps) | C17: 0.6 | D17: =$C$12*C17 -> 22857.633 | E17: 0.075 | F17: =D17*E17 -> 1714.3225
A18: Senior Notes | C18: 0.4 | D18: =$C$12*C18 -> 15238.422 | E18: 0.08 | F18: =D18*E18 -> 1219.0738
A19: Total | C19: =SUM(C17:C18) -> 1 | D19: =SUM(D17:D18) -> 38096.055 | F19: =SUM(F17:F18) -> 2933.3962
A20: Blended cost of debt | C20: =F19/D19 -> 0.077
A21: Entry leverage (Total Debt / EBITDA) | C21: =C12/C6 -> 5.225
A23: OPERATING & CASH FLOW PROJECTIONS
C24: FY2025E | D24: FY2026E | E24: FY2027E | F24: FY2028E | G24: FY2029E
A25: Revenue | C25: =IS!E7 -> 51618.81 | D25: =IS!F7 -> 53425.468 | E25: =IS!G7 -> 55829.614 | F25: =E25*(1+F39) -> 58062.799 | G25: =F25*(1+G39) -> 60385.311
A26: EBITDA | C26: =IS!E25 -> 7355.6804 | D26: =IS!F25 -> 8040.533 | E26: =IS!G25 -> 8793.1643 | F26: =E26*(1+F39) -> 9144.8908 | G26: =F26*(1+G39) -> 9510.6865
A27: EBITDA margin % | C27: =C26/C25 -> 0.1425 | D27: =D26/D25 -> 0.1505 | E27: =E26/E25 -> 0.1575 | F27: =F26/F25 -> 0.1575 | G27: =G26/G25 -> 0.1575
A28: Less: D&A | C28: =IS!E26 -> 800.09155 | D28: =IS!F26 -> 828.09476 | E28: =IS!G26 -> 865.35902 | F28: =E28*(1+F39) -> 899.97338 | G28: =F28*(1+G39) -> 935.97232
A29: EBIT | C29: =C26-C28 -> 6555.5889 | D29: =D26-D28 -> 7212.4382 | E29: =E26-E28 -> 7927.8052 | F29: =F26-F28 -> 8244.9175 | G29: =G26-G28 -> 8574.7142
A30: Less: cash interest | C30: =-C47 -> -2933.3962 | D30: =-D47 -> -2712.6959 | E30: =-E47 -> -2436.0563 | F30: =-F47 -> -2102.377 | G30: =-G47 -> -1727.9636
A31: Pre-tax income | C31: =C29+C30 -> 3622.1926 | D31: =D29+D30 -> 4499.7424 | E31: =E29+E30 -> 5491.749 | F31: =F29+F30 -> 6142.5404 | G31: =G29+G30 -> 6846.7505
A32: Less: taxes | C32: =-MAX(0,C31)*$C$40 -> -633.88371 | D32: =-MAX(0,D31)*$C$40 -> -787.45491 | E32: =-MAX(0,E31)*$C$40 -> -961.05607 | F32: =-MAX(0,F31)*$C$40 -> -1074.9446 | G32: =-MAX(0,G31)*$C$40 -> -1198.1813
A33: Net income | C33: =C31+C32 -> 2988.3089 | D33: =D31+D32 -> 3712.2875 | E33: =E31+E32 -> 4530.6929 | F33: =F31+F32 -> 5067.5959 | G33: =G31+G32 -> 5648.5692
A34: Plus: D&A | C34: =C28 -> 800.09155 | D34: =D28 -> 828.09476 | E34: =E28 -> 865.35902 | F34: =F28 -> 899.97338 | G34: =G28 -> 935.97232
A35: Less: capital expenditures | C35: =CF!E15 -> -980.75739 | D35: =CF!F15 -> -1015.0839 | E35: =CF!G15 -> -1060.7627 | F35: =E35*(1+F39) -> -1103.1932 | G35: =F35*(1+G39) -> -1147.3209
A36: Less: increase in working capital | C36: =CF!E47 -> 58.595554 | D36: =CF!F47 -> 67.423455 | E36: =CF!G47 -> -1.7924307 | F36: =E36*(1+F39) -> -1.864128 | G36: =F36*(1+G39) -> -1.9386931
A37: Free Cash Flow (pre debt paydown) | C37: =C33+C34+C35+C36 -> 2866.2386 | D37: =D33+D34+D35+D36 -> 3592.7218 | E37: =E33+E34+E35+E36 -> 4333.4968 | F37: =F33+F34+F35+F36 -> 4862.5119 | G37: =G33+G34+G35+G36 -> 5435.2819
A39: Stub-year growth (FY28–FY29) | F39: 0.04 | G39: 0.04
A40: LBO tax rate | C40: 0.175
A43: DEBT SCHEDULE (100% cash sweep)
C44: FY2025E | D44: FY2026E | E44: FY2027E | F44: FY2028E | G44: FY2029E
A45: Debt — beginning of year | C45: =C12 -> 38096.055 | D45: =C50 -> 35229.816 | E45: =D50 -> 31637.095 | F45: =E50 -> 27303.598 | G45: =F50 -> 22441.086
A46: Blended interest rate | C46: =$C$20 -> 0.077 | D46: =$C$20 -> 0.077 | E46: =$C$20 -> 0.077 | F46: =$C$20 -> 0.077 | G46: =$C$20 -> 0.077
A47: Cash interest expense | C47: =C45*C46 -> 2933.3962 | D47: =D45*D46 -> 2712.6959 | E47: =E45*E46 -> 2436.0563 | F47: =F45*F46 -> 2102.377 | G47: =G45*G46 -> 1727.9636
...

Sheet Merger
A1: Nike / Skechers — Merger Model (Accretion / Dilution)
A4: TRANSACTION ASSUMPTIONS
A5: Skechers standalone equity value | C5: =Comps!E8 -> 9483.93
A6: Offer premium | C6: 0.225
A7: Implied purchase price (equity) | C7: =C5*(1+C6) -> 11617.814
A8: Plus: target net debt assumed | C8: =Comps!F8 -> -120
A9: Implied transaction enterprise value | C9: =C7+C8 -> 11497.814
A10: Implied EV / LTM EBITDA | C10: =C9/Comps!I8 -> 9.7439104
A11: Stock consideration % | C11: 0.7
A12: Cash / new debt consideration % | C12: =1-C11 -> 0.3
A13: Interest rate on new acquisition debt | C13: 0.055
A14: Nike share price | C14: =WACC!C5 -> 75
A15: New Nike shares issued (mm) | C15: =C7*C11/C14 -> 108.43293
A16: New acquisition debt raised | C16: =C7*C12 -> 3485.3443
A18: SYNERGIES
A19: Run-rate synergies (% of combined revenue) | C19: 0.02
A20: Combined revenue (FY2025E) | C20: =IS!E7+Comps!H8 -> 61028.81
A21: Full run-rate synergies | C21: =C19*C20 -> 1220.5762
C22: Phase-in % | D22: Year 1 | E22: Year 2 | F22: Year 3
A23: Synergy phase-in | D23: 0.33 | E23: 0.67 | F23: 1
A24: Synergies realised | D24: =$C$21*D23 -> 402.79015 | E24: =$C$21*E23 -> 817.78605 | F24: =$C$21*F23 -> 1220.5762
A26: ACCRETION / DILUTION (FY2025E pro forma, Year 1 synergies)
A27: Nike standalone net income | C27: =IS!E21 -> 5635.8598
A28: Skechers standalone net income | C28: 639.5
A29: Plus: after-tax synergies (Year 1) | C29: =D24*(1-(IS!E20/IS!E19)) -> 338.34372
A30: Less: after-tax interest on new debt | C30: =-C16*C13*(1-(IS!E20/IS!E19)) -> -161.02291
A31: Less: after-tax foregone interest on cash | C31: 0
A32: Pro forma net income | C32: =SUM(C27:C31) -> 6452.6806
A34: Nike standalone diluted shares (mm) | C34: =IS!E23 -> 1489.5075
A35: Plus: new shares issued (mm) | C35: =C15 -> 108.43293
A36: Pro forma diluted shares (mm) | C36: =C34+C35 -> 1597.9404
A38: Nike standalone EPS | C38: =IS!E22 -> 3.7837069
A39: Pro forma EPS | C39: =C32/C36 -> 4.0381234
A40: Accretion / (dilution) — $ | C40: =C39-C38 -> 0.25441648
A41: Accretion / (dilution) — % | C41: =C39/C38-1 -> 0.067240008
A43: Breakeven synergies required ($mm, pre-tax) | C43: =((C38*C36)-(C27+C28+C30+C31))/(1-(IS!E20/IS!E19)) -> -81.188881
A46: SCENARIO COMPARISON — CASH vs STOCK vs MIXED CONSIDERATION
C48: All-Cash | D48: All-Stock | E48: Mixed (Deal Terms)
A49: Stock consideration % | C49: 0 | D49: 1 | E49: =$C$11 -> 0.7
A50: Cash / new debt consideration % | C50: =1-C49 -> 1 | D50: =1-D49 -> 0 | E50: =1-E49 -> 0.3
...

Sheet Football Field
A1: NIKE, Inc. — Valuation Summary (Football Field)
A5: Methodology | B5: Low | C5: Midpoint | D5: High | E5: Range Width | F5: Basis
A6: DCF — WACC ± 50bps, g ± 50bps | B6: =MIN(DCF!C44:G48) -> 49.434412 | C6: =DCF!C37 -> 62.048819 | D6: =MAX(DCF!C44:G48) -> 85.408967 | E6: =D6-B6 -> 35.974555 | F6: Sensitivity grid corners
A7: Trading comps — EV / EBITDA | B7: =Comps!G31 -> 26.922084 | C7: =Comps!G29 -> 51.113608 | D7: =Comps!G33 -> 139.78345 | E7: =D7-B7 -> 112.86137 | F7: Peer low / median / high
A8: Trading comps — EV / Revenue | B8: =Comps!G30 -> 19.4418 | C8: =Comps!G28 -> 41.623603 | D8: =Comps!G32 -> 179.19626 | E8: =D8-B8 -> 159.75446 | F8: Peer low / median / high
A9: Precedent transactions — EV / EBITDA | B9: =Precedents!G24 -> 36.197568 | C9: =Precedents!G23 -> 56.833509 | D9: =Precedents!G25 -> 76.30072 | E9: =D9-B9 -> 40.103152 | F9: Deal low / median / high
A10: LBO — sponsor-affordable value | B10: =LBO!C7*0.85/WACC!C6 -> 38.538798 | C10: =LBO!C7/WACC!C6 -> 45.339762 | D10: =LBO!C7*1.1/WACC!C6 -> 49.873738 | E10: =D10-B10 -> 11.334941 | F10: Entry EV at 9.5x, ±
A12: Overall range (excl. LBO) | B12: =MIN(B6:B9) -> 19.4418 | C12: =MEDIAN(C6:C9) -> 53.973558 | D12: =MAX(D6:D9) -> 179.19626
A14: Current share price | B14: =WACC!C5 -> 75
A15: Position vs blended midpoint | B15: =C12/B14-1 -> -0.28035255
